<?xml version="1.0"?>
<robot name="differential_drive_robot">
  <link name="base_link">
    <visual>
    <origin xyz="0 0 0" rpy="1.57 0 0" />
      <geometry>
        <mesh filename="body.stl"/>
      </geometry>
    </visual>
    <collision>
     <origin xyz="0 0 0" rpy="1.57 0 0" />
      <geometry>
        <mesh filename="body.stl"/>
      </geometry>
    </collision>
    <inertial>
      <mass value="2.3" />
      <origin xyz="0.1 0 0" rpy="0 0 0" />
      <inertia ixx="0.0001" ixy="0" ixz="0" iyy="0.0001" iyz="0" izz="0.001" />
    </inertial>
  </link>

  <link name="left_wheel">
    <visual>
      <origin xyz="0 0 0" rpy=" 1.57 0 0" />
      <geometry>
        <cylinder length="0.05" radius="0.14" />
      </geometry>
      <!-- <material name="Cyan"> 14 <color rgba="0 1.0 1.0 1.0" /> 15 </material> -->
    </visual>
    <collision>
      <origin xyz="0 0 0" rpy=" 1.57 0 0" />
      <geometry>
        <cylinder length="0.05" radius="0.14" />
      </geometry>
    </collision>
    <inertial>
      <mass value="0.2" />
      <inertia ixx="0.01" ixy="0" ixz="0" iyy="0.01" iyz="0" izz="0.01" />
    </inertial>
  </link>

  <link name="right_wheel">
    <visual>
      <origin xyz="0 0 0" rpy=" 1.57 0 0" />
      <geometry>
        <cylinder length="0.05" radius="0.14" />
      </geometry>
    </visual>
    <collision>
      <origin xyz="0 0 0" rpy=" 1.57 0 0" />
      <geometry>
        <cylinder length="0.05" radius="0.14" />
      </geometry>
    </collision>
    <inertial>
      <mass value="0.2" />
      <origin xyz="0 0 0" rpy="0 0 0" />
      <inertia ixx="0.01" ixy="0" ixz="0" iyy="0.01" iyz="0" izz="0.01" />
    </inertial>
  </link>
  <!-- 
  <link name="caster">
    <visual>
      <geometry>
        <sphere radius="0.05" />
      </geometry>
    </visual>
    <collision>
      <geometry>
        <sphere radius="0.05" />
      </geometry>
    </collision>
    <inertial>
      <mass value="0.1" />
      <origin xyz="0 0 0" rpy="0 0 0" />
      <inertia ixx="0.0001" ixy="0" ixz="0" iyy="0.0001" iyz="0" izz="0.0001" />
    </inertial>
  </link> -->

  <!-- <joint name="base_link_to_caster" type="fixed">
    <parent link="base_link" />
    <child link="caster" />
    <origin xyz="0.25 0 -0.1" />
  </joint> -->

  <joint name="left_wheel_joint" type="continuous">
    <parent link="base_link" />
    <child link="left_wheel" />
    <origin xyz="0.02 0.175 0" rpy="0 0 0" />
    <axis xyz="0 1 0" />
    <!-- <limit effort="100" velocity="5" /> -->
  </joint>

  <joint name="right_wheel_joint" type="continuous">
    <parent link="base_link" />
    <child link="right_wheel" />
    <origin xyz="0.02 -0.175 0" rpy="0 0 0" />
    <axis xyz="0 1 0" />
  </joint>
</robot>